Workbook

Sheet raw_data
A1: employee_name | B1: test | C1: score | D1: max_score
A2: Samuel Rachene | B2: Safety | C2: 9 | D2: 10
A3: Samuel Rachene | B3: Company Philosophy | C3: 14 | D3: 20
A4: Samuel Rachene | B4: Financial Skills | C4: 83 | D4: 100
A5: Samuel Rachene | B5: Drug Test | C5: 1 | D5: 1
A6: Eugena Esser | B6: Safety | C6: 2 | D6: 10
A7: Eugena Esser | B7: Company Philosophy | C7: 3 | D7: 20
A8: Eugena Esser | B8: Financial Skills | C8: 12 | D8: 100
A9: Eugena Esser | B9: Drug Test | C9: 0 | D9: 1
A10: Michel Averette | B10: Safety | C10: 7 | D10: 10
A11: Michel Averette | B11: Company Philosophy | C11: 19 | D11: 20
A12: Michel Averette | B12: Financial Skills | C12: 47 | D12: 100
A13: Michel Averette | B13: Drug Test | C13: 1 | D13: 1
... A89: Sherlene Wetherington | B89: Drug Test | C89: 0 | D89: 1

Sheet calculations
A1: employee_name | B1: test | C1: score | D1: max_score | E1: percentage | F1: total score per employee | G1: total_max_score | H1: overall_score | I1: grade | J1: pass/fail
A2: {=Table1[]} -> Samuel Rachene | B2: Safety | C2: 9 | D2: 10 | E2: =C2/D2 -> 0.9 | F2: =SUMIF(A:A,A2,C:C) -> 107 | G2: =SUMIF(A:A,A2,D:D) -> 131 | H2: =F2/G2 -> 0.81679389 | I2: =IF(F2>=90,"A",IF(F2>=75,"B",IF(F2>=60,"C",IF(F2>=40,"D","F")))) -> A | J2: =IF(H2>=50%,"Pass","Fail") -> Pass
A3: Samuel Rachene | B3: Company Philosophy | C3: 14 | D3: 20 | E3: =C3/D3 -> 0.7 | F3: =SUMIF(A:A,A3,C:C) -> 107 | G3: =SUMIF(A:A,A3,D:D) -> 131 | H3: =F3/G3 -> 0.81679389 | I3: =IF(F3>=90,"A",IF(F3>=75,"B",IF(F3>=60,"C",IF(F3>=40,"D","F")))) -> A | J3: =IF(H3>=50%,"Pass","Fail") -> Pass
A4: Samuel Rachene | B4: Financial Skills | C4: 83 | D4: 100 | E4: =C4/D4 -> 0.83 | F4: =SUMIF(A:A,A4,C:C) -> 107 | G4: =SUMIF(A:A,A4,D:D) -> 131 | H4: =F4/G4 -> 0.81679389 | I4: =IF(F4>=90,"A",IF(F4>=75,"B",IF(F4>=60,"C",IF(F4>=40,"D","F")))) -> A | J4: =IF(H4>=50%,"Pass","Fail") -> Pass
A5: Samuel Rachene | B5: Drug Test | C5: 1 | D5: 1 | E5: =C5/D5 -> 1 | F5: =SUMIF(A:A,A5,C:C) -> 107 | G5: =SUMIF(A:A,A5,D:D) -> 131 | H5: =F5/G5 -> 0.81679389 | I5: =IF(F5>=90,"A",IF(F5>=75,"B",IF(F5>=60,"C",IF(F5>=40,"D","F")))) -> A | J5: =IF(H5>=50%,"Pass","Fail") -> Pass
A6: Eugena Esser | B6: Safety | C6: 2 | D6: 10 | E6: =C6/D6 -> 0.2 | F6: =SUMIF(A:A,A6,C:C) -> 17 | G6: =SUMIF(A:A,A6,D:D) -> 131 | H6: =F6/G6 -> 0.12977099 | I6: =IF(F6>=90,"A",IF(F6>=75,"B",IF(F6>=60,"C",IF(F6>=40,"D","F")))) -> F | J6: =IF(H6>=50%,"Pass","Fail") -> Fail
A7: Eugena Esser | B7: Company Philosophy | C7: 3 | D7: 20 | E7: =C7/D7 -> 0.15 | F7: =SUMIF(A:A,A7,C:C) -> 17 | G7: =SUMIF(A:A,A7,D:D) -> 131 | H7: =F7/G7 -> 0.12977099 | I7: =IF(F7>=90,"A",IF(F7>=75,"B",IF(F7>=60,"C",IF(F7>=40,"D","F")))) -> F | J7: =IF(H7>=50%,"Pass","Fail") -> Fail
A8: Eugena Esser | B8: Financial Skills | C8: 12 | D8: 100 | E8: =C8/D8 -> 0.12 | F8: =SUMIF(A:A,A8,C:C) -> 17 | G8: =SUMIF(A:A,A8,D:D) -> 131 | H8: =F8/G8 -> 0.12977099 | I8: =IF(F8>=90,"A",IF(F8>=75,"B",IF(F8>=60,"C",IF(F8>=40,"D","F")))) -> F | J8: =IF(H8>=50%,"Pass","Fail") -> Fail
A9: Eugena Esser | B9: Drug Test | C9: 0 | D9: 1 | E9: =C9/D9 -> 0 | F9: =SUMIF(A:A,A9,C:C) -> 17 | G9: =SUMIF(A:A,A9,D:D) -> 131 | H9: =F9/G9 -> 0.12977099 | I9: =IF(F9>=90,"A",IF(F9>=75,"B",IF(F9>=60,"C",IF(F9>=40,"D","F")))) -> F | J9: =IF(H9>=50%,"Pass","Fail") -> Fail
A10: Michel Averette | B10: Safety | C10: 7 | D10: 10 | E10: =C10/D10 -> 0.7 | F10: =SUMIF(A:A,A10,C:C) -> 74 | G10: =SUMIF(A:A,A10,D:D) -> 131 | H10: =F10/G10 -> 0.5648855 | I10: =IF(F10>=90,"A",IF(F10>=75,"B",IF(F10>=60,"C",IF(F10>=40,"D","F")))) -> C | J10: =IF(H10>=50%,"Pass","Fail") -> Pass
A11: Michel Averette | B11: Company Philosophy | C11: 19 | D11: 20 | E11: =C11/D11 -> 0.95 | F11: =SUMIF(A:A,A11,C:C) -> 74 | G11: =SUMIF(A:A,A11,D:D) -> 131 | H11: =F11/G11 -> 0.5648855 | I11: =IF(F11>=90,"A",IF(F11>=75,"B",IF(F11>=60,"C",IF(F11>=40,"D","F")))) -> C | J11: =IF(H11>=50%,"Pass","Fail") -> Pass
A12: Michel Averette | B12: Financial Skills | C12: 47 | D12: 100 | E12: =C12/D12 -> 0.47 | F12: =SUMIF(A:A,A12,C:C) -> 74 | G12: =SUMIF(A:A,A12,D:D) -> 131 | H12: =F12/G12 -> 0.5648855 | I12: =IF(F12>=90,"A",IF(F12>=75,"B",IF(F12>=60,"C",IF(F12>=40,"D","F")))) -> C | J12: =IF(H12>=50%,"Pass","Fail") -> Pass
A13: Michel Averette | B13: Drug Test | C13: 1 | D13: 1 | E13: =C13/D13 -> 1 | F13: =SUMIF(A:A,A13,C:C) -> 74 | G13: =SUMIF(A:A,A13,D:D) -> 131 | H13: =F13/G13 -> 0.5648855 | I13: =IF(F13>=90,"A",IF(F13>=75,"B",IF(F13>=60,"C",IF(F13>=40,"D","F")))) -> C | J13: =IF(H13>=50%,"Pass","Fail") -> Pass
A14: Renetta Carew | B14: Safety | C14: 4 | D14: 10 | E14: =C14/D14 -> 0.4 | F14: =SUMIF(A:A,A14,C:C) -> 17 | G14: =SUMIF(A:A,A14,D:D) -> 131 | H14: =F14/G14 -> 0.12977099 | I14: =IF(F14>=90,"A",IF(F14>=75,"B",IF(F14>=60,"C",IF(F14>=40,"D","F")))) -> F | J14: =IF(H14>=50%,"Pass","Fail") -> Fail
... A89: Sherlene Wetherington | B89: Drug Test | C89: 0 | D89: 1 | E89: =C89/D89 -> 0 | F89: =SUMIF(A:A,A89,C:C) -> 82 | G89: =SUMIF(A:A,A89,D:D) -> 131 | H89: =F89/G89 -> 0.6259542 | I89: =IF(F89>=90,"A",IF(F89>=75,"B",IF(F89>=60,"C",IF(F89>=40,"D","F")))) -> B | J89: =IF(H89>=50%,"Pass","Fail") -> Pass

Sheet helper
A1: Count of employee_name | B1: Column Labels
A2: Row Labels | B2: Pass
A3: Akilah Drinkard | B3: 1
A4: Ayesha Monica | B4: 1
A5: Cara Clarke | B5: 1
A6: Elba Felder | B6: 1
A7: Ernestine Pickrone | B7: 1
A8: Giana Dossey | B8: 1
A9: Michel Averette | B9: 1
A10: Nakesha Renn | B10: 1
A11: Necole Victory | B11: 1
A12: Samuel Rachene | B12: 1
A13: Sherlene Wetherington | B13: 1
A14: Tia Amato | B14: 1
A15: Grand Total | B15: 12

Sheet analysis
A1: Employee Training Assessment Dashboard
A3: Total Employees | B3: =COUNTA(_xlfn.UNIQUE(calculations!A2:A89)) -> 22 | D3: Top 5 Employees
A4: Average Overall Score | B4: =AVERAGEA(_xlfn.UNIQUE(calculations!H:H)) -> 0.48396947 | D4: Employee Name | E4: Overall Score
A5: Pass Rate (%) | B5: =GETPIVOTDATA("employee_name",helper!$A$1,"final_pass_fail","Pass")/analysis!B3 -> 0.54545455 | D5: Cara Clarke | E5: 0.93129771
A6: Fail Count | B6: =B3-GETPIVOTDATA("employee_name",helper!$A$1,"final_pass_fail","Pass") -> 10 | D6: Ayesha Monica | E6: 0.87022901
A7: Top Performer | B7: =INDEX(A50:A72,MATCH(MAX(B50:B72),B50:B72,0)) -> Cara Clarke | D7: Samuel Rachene | E7: 0.81679389
A8: Worst Performer | B8: =INDEX(A50:A72,MATCH(MIN(B50:B72),B50:B72,0)) -> Eugena Esser | D8: Tia Amato | E8: 0.81679389
D9: Giana Dossey | E9: 0.80152672
A11: Insights:
A12: * Overall performance is low with average score of 48%
A13: * 45% of employees failed at least one test
A14: * Financial Skills has the lowest average score (~49%), indicating a major skill gap
A15: * Safety test shows the highest performance (~60%), indicating better compliance
A16: understanding
A17: * Cara Clarke is the top performer with 93% | B17: significantly above average
A19: Recommendations:
A20: * Conduct focused training programs on Financial Skills
A21: * Provide support plans for employees scoring below 50%
A22: * Reassess training content for weak areas
A23: * Track performance over time with periodic assessments
A50: Employee Name | B50: Overall Score | D50: Result | E50: Count
A51: Cara Clarke | B51: 0.93129771 | D51: Pass | E51: =GETPIVOTDATA("employee_name",helper!$A$1,"final_pass_fail","Pass") -> 12
A52: Ayesha Monica | B52: 0.87022901 | D52: Fail | E52: =B6 -> 10
A53: Samuel Rachene | B53: 0.81679389
A54: Tia Amato | B54: 0.81679389 | D54: Test Name | E54: Avg Score
A55: Giana Dossey | B55: 0.80152672 | D55: Safety | E55: =AVERAGEIF(calculations!B:B,"Safety",calculations!E:E) -> 0.58181818
A56: Sherlene Wetherington | B56: 0.6259542 | D56: Company Philosophy | E56: =AVERAGEIF(calculations!B:B,"Company Philosophy",calculations!E:E) -> 0.54772727
A57: Ernestine Pickrone | B57: 0.61832061 | D57: Drug Test | E57: =AVERAGEIF(calculations!B:B,"Drug Test",calculations!E:E) -> 0.5
A58: Elba Felder | B58: 0.61068702 | D58: Financial Skills | E58: =AVERAGEIF(calculations!B:B,"Financial Skills",calculations!E:E) -> 0.49136364
A59: Necole Victory | B59: 0.58015267
A60: Michel Averette | B60: 0.5648855
A61: Akilah Drinkard | B61: 0.52671756
A62: Nakesha Renn | B62: 0.52671756
A63: Retha Sears | B63: 0.48091603
A64: Shawanda Selke | B64: 0.4351145
A65: Lavera Oles | B65: 0.36641221
A66: Elna Condello | B66: 0.34351145
A67: Debroah Wardle | B67: 0.32061069
A68: Julia Behrman | B68: 0.27480916
A69: Silvana Virden | B69: 0.22900763
...
